<?xml version="1.0"?>

<robot name="diff_drive"  xmlns:xacro="http://www.ros.org/wiki/xacro">
<link name="base_footprint">
    <visual>
        <origin xyz="0 0 0" rpy="0 0 0" />
        <geometry>
            <box size="0.001 0.001 0.001" />
        </geometry>
    </visual>
</link>

<joint name="base_footprint_joint" type="fixed">
    <origin xyz="0 0 0.001" rpy="0 0 0" />
    <parent link="base_footprint"/>
    <child link="base_link" />
</joint>

  <link
    name="base_link">
    <inertial>
      <origin
        xyz="0.075437 -0.081571 1.5777"
        rpy="0 0 0" />
      <mass
        value="15.9117" />
      <inertia
        ixx="0.34531"
        ixy="4.5025E-05"
        ixz="4.9852E-05"
        iyy="0.48046"
        iyz="-0.0015465"
        izz="0.15682" />
    </inertial>
    <visual>
      <origin
        xyz="0 0 0"
        rpy="0 0 0" />
      <geometry>
        <mesh
          filename="package://diff_drive/meshes/visual/base_link.STL" />
      </geometry>
      <material
        name="">
        <color
          rgba="1 1 0 1" />
      </material>
    </visual>
    <collision>
      <origin
        xyz="0 0 0"
        rpy="0 0 0" />
      <geometry>
        <mesh
          filename="package://diff_drive/meshes/visual/base_link.STL" />
      </geometry>
    </collision>
  </link>
  <link
    name="casterSupportRight">
    <inertial>
      <origin
        xyz="0.033713 0.1735 -0.0018944"
        rpy="0 0 0" />
      <mass
        value="1.461" />
      <inertia
        ixx="0.00039179"
        ixy="5.1241E-18"
        ixz="-1.9368E-07"
        iyy="0.00076151"
        iyz="-2.6793E-21"
        izz="0.00056178" />
    </inertial>
    <visual>
      <origin
        xyz="0 0 0"
        rpy="0 0 0" />
      <geometry>
        <mesh
          filename="package://diff_drive/meshes/visual/casterSupportRight.STL" />
      </geometry>
      <material
        name="">
        <color
          rgba="0.29412 0.29412 0.29412 1" />
      </material>
    </visual>
    <collision>
      <origin
        xyz="0 0 0"
        rpy="0 0 0" />
      <geometry>
        <mesh
          filename="package://diff_drive/meshes/visual/casterSupportRight.STL" />
      </geometry>
    </collision>
  </link>
  <joint
    name="caster_support_right"
    type="fixed">
    <origin
      xyz="-0.36024 -1.0733 -0.27044"
      rpy="1.5708 0 0" />
    <parent
      link="base_link" />
    <child
      link="casterSupportRight" />
    <axis
      xyz="0 0 0" />
  </joint>
  <link
    name="casterHolderRight">
    <inertial>
      <origin
        xyz="0.0382993385883101 0.117904792850938 0.00015159223218264"
        rpy="0 0 0" />
      <mass
        value="0.0833209061257809" />
      <inertia
        ixx="6.38101809119889E-05"
        ixy="-3.93281226439366E-09"
        ixz="-1.3645801878724E-07"
        iyy="8.28702382004282E-05"
        iyz="-1.11409223619846E-08"
        izz="8.0612581771544E-05" />
    </inertial>
    <visual>
      <origin
        xyz="0 0 0"
        rpy="0 0 0" />
      <geometry>
        <mesh
          filename="package://diff_drive/meshes/visual/casterHolderRight.STL" />
      </geometry>
      <material
        name="">
        <color
          rgba="0.792156862745098 0.819607843137255 0.933333333333333 1" />
      </material>
    </visual>
    <collision>
      <origin
        xyz="0 0 0"
        rpy="0 0 0" />
      <geometry>
        <mesh
          filename="package://diff_drive/meshes/visual/casterHolderRight.STL" />
      </geometry>
    </collision>
  </link>
  <joint
    name="caster_holder_right"
    type="fixed">
    <origin
      xyz="0 0 0"
      rpy="0 0 0" />
    <parent
      link="casterSupportRight" />
    <child
      link="casterHolderRight" />
    <axis
      xyz="0 0 0" />
  </joint>
  <link
    name="casterWheelRight">
    <inertial>
      <origin
        xyz="0.035994922829838 -0.00170632473366483 -0.00091408050687547"
        rpy="0 0 0" />
      <mass
        value="0.43467616518886" />
      <inertia
        ixx="0.00157044446597303"
        ixy="-2.6753199634683E-18"
        ixz="-1.37055216395096E-17"
        iyy="0.000855077607653301"
        iyz="-3.93145810217666E-20"
        izz="0.000855077607653301" />
    </inertial>
    <visual>
      <origin
        xyz="0 0 0"
        rpy="0 0 0" />
      <geometry>
        <mesh
          filename="package://diff_drive/meshes/visual/casterWheelRight.STL" />
      </geometry>
      <material
        name="">
        <color
          rgba="0.752941176470588 0 0 1" />
      </material>
    </visual>
    <collision>
      <origin
        xyz="0 0 0"
        rpy="0 0 0" />
      <geometry>
        <mesh
          filename="package://diff_drive/meshes/visual/casterWheelRight.STL" />
      </geometry>
    </collision>
  </link>
  <joint
    name="caster_wheel_right"
    type="continuous">
    <origin
      xyz="0 0 0"
      rpy="0 0 0" />
    <parent
      link="casterHolderRight" />
    <child
      link="casterWheelRight" />
    <axis
      xyz="1 0 0" />
    <limit
      effort="1"
      velocity="10" />
  </joint>
  <link
    name="casterRIghtTIre">
    <inertial>
      <origin
        xyz="0.0359640162857298 -0.00170632473566662 -0.000914080509161197"
        rpy="0 0 0" />
      <mass
        value="0.810225403265173" />
      <inertia
        ixx="0.00560952480151363"
        ixy="-6.12139598887725E-17"
        ixz="-4.8595826569797E-17"
        iyy="0.00294745006429648"
        iyz="-2.25310763969679E-19"
        izz="0.00294745006429648" />
    </inertial>
    <visual>
      <origin
        xyz="0 0 0"
        rpy="0 0 0" />
      <geometry>
        <mesh
          filename="package://diff_drive/meshes/visual/casterRIghtTIre.STL" />
      </geometry>
      <material
        name="">
        <color
          rgba="0.250980392156863 0.250980392156863 0.250980392156863 1" />
      </material>
    </visual>
    <collision>
      <origin
        xyz="0 0 0"
        rpy="0 0 0" />
      <geometry>
        <mesh
          filename="package://diff_drive/meshes/visual/casterRIghtTIre.STL" />
      </geometry>
    </collision>
  </link>
  <joint
    name="caster_right_tire"
    type="fixed">
    <origin
      xyz="0 0 0"
      rpy="0 0 0" />
    <parent
      link="casterWheelRight" />
    <child
      link="casterRIghtTIre" />
    <axis
      xyz="0 0 0" />
  </joint>
  <link
    name="casterSupportLeft">
    <inertial>
      <origin
        xyz="-0.043787 0.1735 -0.0018944"
        rpy="0 0 0" />
      <mass
        value="1.46095" />
      <inertia
        ixx="0.00039179"
        ixy="4.8867E-18"
        ixz="-1.9368E-07"
        iyy="0.00076151"
        iyz="-7.1557E-20"
        izz="0.00056178" />
    </inertial>
    <visual>
      <origin
        xyz="0 0 0"
        rpy="0 0 0" />
      <geometry>
        <mesh
          filename="package://diff_drive/meshes/visual/casterSupportLeft.STL" />
      </geometry>
      <material
        name="">
        <color
          rgba="0.29412 0.29412 0.29412 1" />
      </material>
    </visual>
    <collision>
      <origin
        xyz="0 0 0"
        rpy="0 0 0" />
      <geometry>
        <mesh
          filename="package://diff_drive/meshes/visual/casterSupportLeft.STL" />
      </geometry>
    </collision>
  </link>
  <joint
    name="caster_support_left"
    type="fixed">
    <origin
      xyz="0.51626 -1.0733 -0.27044"
      rpy="1.5708 0 0" />
    <parent
      link="base_link" />
    <child
      link="casterSupportLeft" />
    <axis
      xyz="0 0 0" />
  </joint>
  <link
    name="casterHolderLeft">
    <inertial>
      <origin
        xyz="-0.0387518671119899 0.128982529098677 0.000165835118948632"
        rpy="0 0 0" />
      <mass
        value="0.0761648437855795" />
      <inertia
        ixx="6.36826685886144E-05"
        ixy="-3.93273626686909E-09"
        ixz="-1.36457921864003E-07"
        iyy="7.86417547468484E-05"
        iyz="-1.11410722720765E-08"
        izz="7.63840982656631E-05" />
    </inertial>
    <visual>
      <origin
        xyz="0 0 0"
        rpy="0 0 0" />
      <geometry>
        <mesh
          filename="package://diff_drive/meshes/visual/casterHolderLeft.STL" />
      </geometry>
      <material
        name="">
        <color
          rgba="0.792156862745098 0.819607843137255 0.933333333333333 1" />
      </material>
    </visual>
    <collision>
      <origin
        xyz="0 0 0"
        rpy="0 0 0" />
      <geometry>
        <mesh
          filename="package://diff_drive/meshes/visual/casterHolderLeft.STL" />
      </geometry>
    </collision>
  </link>
  <joint
    name="caster_holder_left"
    type="fixed">
    <origin
      xyz="0 0 0"
      rpy="0 0 0" />
    <parent
      link="casterSupportLeft" />
    <child
      link="casterHolderLeft" />
    <axis
      xyz="0 0 0" />
  </joint>
  <link
    name="casterWheelLeft">
    <inertial>
      <origin
        xyz="-0.0415050771701638 0.00261917329426858 0.0003715776122033"
        rpy="0 0 0" />
      <mass
        value="0.434676165188859" />
      <inertia
        ixx="0.00157044446597303"
        ixy="-3.63891563040551E-18"
        ixz="-1.24071945642976E-17"
        iyy="0.0008550776076533"
        iyz="1.78859253738196E-20"
        izz="0.000855077607653301" />
    </inertial>
    <visual>
      <origin
        xyz="0 0 0"
        rpy="0 0 0" />
      <geometry>
        <mesh
          filename="package://diff_drive/meshes/visual/casterWheelLeft.STL" />
      </geometry>
      <material
        name="">
        <color
          rgba="0.752941176470588 0 0 1" />
      </material>
    </visual>
    <collision>
      <origin
        xyz="0 0 0"
        rpy="0 0 0" />
      <geometry>
        <mesh
          filename="package://diff_drive/meshes/visual/casterWheelLeft.STL" />
      </geometry>
    </collision>
  </link>
  <joint
    name="caster_wheel_left"
    type="continuous">
    <origin
      xyz="0 0 0"
      rpy="0 0 0" />
    <parent
      link="casterHolderLeft" />
    <child
      link="casterWheelLeft" />
    <axis
      xyz="1 0 0" />
    <limit
      effort="1"
      velocity="10" />
    <dynamics
      damping="1"
      friction="1" />
  </joint>
  <link
    name="casterTireLeft">
    <inertial>
      <origin
        xyz="-0.0425846574963772 0.00261917329104561 0.000371577609860951"
        rpy="0 0 0" />
      <mass
        value="0.810225403265173" />
      <inertia
        ixx="0.00560952480151363"
        ixy="-5.87359604787391E-17"
        ixz="-4.59628823694464E-17"
        iyy="0.00294745006429648"
        iyz="-8.21621958836961E-20"
        izz="0.00294745006429648" />
    </inertial>
    <visual>
      <origin
        xyz="0 0 0"
        rpy="0 0 0" />
      <geometry>
        <mesh
          filename="package://diff_drive/meshes/visual/casterTireLeft.STL" />
      </geometry>
      <material
        name="">
        <color
          rgba="0.250980392156863 0.250980392156863 0.250980392156863 1" />
      </material>
    </visual>
    <collision>
      <origin
        xyz="0 0 0"
        rpy="0 0 0" />
      <geometry>
        <mesh
          filename="package://diff_drive/meshes/visual/casterTireLeft.STL" />
      </geometry>
    </collision>
  </link>
  <joint
    name="caster_tire_left"
    type="fixed">
    <origin
      xyz="0 0 0"
      rpy="0 0 0" />
    <parent
      link="casterWheelLeft" />
    <child
      link="casterTireLeft" />
    <axis
      xyz="0 0 0" />
  </joint>
  <link
    name="chassis">
    <inertial>
      <origin
        xyz="-0.00024879 -0.11547 0.23109"
        rpy="0 0 0" />
      <mass
        value="5.2325" />
      <inertia
        ixx="0.31047"
        ixy="0.00010792"
        ixz="-0.00077258"
        iyy="0.45355"
        iyz="0.01911"
        izz="0.20521" />
    </inertial>
    <visual>
      <origin
        xyz="0 0 0"
        rpy="0 0 0" />
      <geometry>
        <mesh
          filename="package://diff_drive/meshes/visual/chassis.STL" />
      </geometry>
      <material
        name="">
               <color
          rgba="1 1 0 1" />
      </material>
    </visual>
    <collision>
      <origin
        xyz="0 0 0"
        rpy="0 0 0" />
      <geometry>
        <mesh
          filename="package://diff_drive/meshes/visual/chassis.STL" />
      </geometry>
    </collision>
  </link>
  <joint
    name="chassis_top"
    type="fixed">
    <origin
      xyz="0.0769578702021261 -1.52680535726289 0.180738869902464"
      rpy="1.5707963267949 0 0" />
    <parent
      link="base_link" />
    <child
      link="chassis" />
    <axis
      xyz="0 0 0" />
  </joint>
  <link
    name="tower">
    <inertial>
      <origin
        xyz="0.0860662317841651 0.0226377611381061 0.049997707034549"
        rpy="0 0 0" />
      <mass
        value="0.929548157217123" />
      <inertia
        ixx="0.0135570321632158"
        ixy="6.41772677423658E-05"
        ixz="1.3148174470214E-07"
        iyy="0.00860966719928799"
        iyz="2.74387282071566E-07"
        izz="0.0135241113699644" />
    </inertial>
    <visual>
      <origin
        xyz="0 0 0"
        rpy="0 0 0" />
      <geometry>
        <mesh
          filename="package://diff_drive/meshes/visual/tower.STL" />
      </geometry>
      <material
        name="">
        <color
          rgba="0.792156862745098 0.819607843137255 0.933333333333333 1" />
      </material>
    </visual>
    <collision>
      <origin
        xyz="0 0 0"
        rpy="0 0 0" />
      <geometry>
        <mesh
          filename="package://diff_drive/meshes/visual/tower.STL" />
      </geometry>
    </collision>
  </link>
  <joint
    name="tower_"
    type="fixed">
    <origin
      xyz="-0.0863800430095729 0.132355689959803 0.179401745287782"
      rpy="0 0 0" />
    <parent
      link="chassis" />
    <child
      link="tower" />
    <axis
      xyz="0 0 0" />
  </joint>
  <link
    name="towerLid">
    <inertial>
      <origin
        xyz="0.0861751451686685 0.175144310040197 0.0500028904196914"
        rpy="0 0 0" />
      <mass
        value="0.0982469759272593" />
      <inertia
        ixx="0.000283153085900981"
        ixy="5.08021982325599E-18"
        ixz="-4.47354581904874E-12"
        iyy="0.000566158891065147"
        iyz="1.08100857539373E-21"
        izz="0.000283153175628057" />
    </inertial>
    <visual>
      <origin
        xyz="0 0 0"
        rpy="0 0 0" />
      <geometry>
        <mesh
          filename="package://diff_drive/meshes/visual/towerLid.STL" />
      </geometry>
      <material
        name="">
        <color
          rgba="0.792156862745098 0.819607843137255 0.933333333333333 1" />
      </material>
    </visual>
    <collision>
      <origin
        xyz="0 0 0"
        rpy="0 0 0" />
      <geometry>
        <mesh
          filename="package://diff_drive/meshes/visual/towerLid.STL" />
      </geometry>
    </collision>
  </link>
  <joint
    name="tower_lid"
    type="fixed">
    <origin
      xyz="0 0 0"
      rpy="0 0 0" />
    <parent
      link="tower" />
    <child
      link="towerLid" />
    <axis
      xyz="0 0 0" />
  </joint>
  <link
    name="tireRIght">
    <inertial>
      <origin
        xyz="0.11009 7.5916E-06 -2.2334E-05"
        rpy="0 0 0" />
      <mass
        value="9.51472" />
      <inertia
        ixx="0.00050921"
        ixy="-3.2248E-07"
        ixz="9.4966E-07"
        iyy="0.00072702"
        iyz="-1.3419E-08"
        izz="0.00072706" />
    </inertial>
    <visual>
      <origin
        xyz="0 0 0"
        rpy="0 0 0" />
      <geometry>
        <mesh
          filename="package://diff_drive/meshes/visual/tireRIght.STL" />
      </geometry>
      <material
        name="">
        <color
          rgba="0.95686 0.95686 0.96078 1" />
      </material>
    </visual>
    <collision>
      <origin
        xyz="0 0 0"
        rpy="0 0 0" />
      <geometry>
        <mesh
          filename="package://diff_drive/meshes/visual/tireRIght.STL" />
      </geometry>
    </collision>
  </link>
  <joint
    name="tire_right"
    type="fixed">
    <origin
      xyz="-0.387860216208303 -2.14524794513276 -0.202298122418271"
      rpy="1.5707963267949 0 0" />
    <parent
      link="base_link" />
    <child
      link="tireRIght" />
    <axis
      xyz="0 0 0" />
  </joint>
  <link
    name="wheelRight">
    <inertial>
      <origin
        xyz="0.0533246151428162 -2.58176721834591E-07 1.03920091998333E-06"
        rpy="0 0 0" />
      <mass
        value="1.40669832967328" />
      <inertia
        ixx="0.00396065946094497"
        ixy="4.46642758249798E-09"
        ixz="-1.54995930328237E-08"
        iyy="0.00408955213615999"
        iyz="2.57506666522041E-07"
        izz="0.00408898253241259" />
    </inertial>
    <visual>
      <origin
        xyz="0 0 0"
        rpy="0 0 0" />
      <geometry>
        <mesh
          filename="package://diff_drive/meshes/visual/wheelRight.STL" />
      </geometry>
      <material
        name="">
        <color
          rgba="0.792156862745098 0.819607843137255 0.933333333333333 1" />
      </material>
    </visual>
    <collision>
      <origin
        xyz="0 0 0"
        rpy="0 0 0" />
      <geometry>
        <mesh
          filename="package://diff_drive/meshes/visual/wheelRight.STL" />
      </geometry>
    </collision>
  </link>
  <joint
    name="wheel_right"
    type="continuous">
    <origin
      xyz="0 0 0"
      rpy="0 0 0" />
    <parent
      link="tireRIght" />
    <child
      link="wheelRight" />
    <axis
      xyz="-1 0 0" />
    <limit
      effort="1"
      velocity="100" />
  </joint>
  <link
    name="tyreRight">
    <inertial>
      <origin
        xyz="0.0680190209858414 -1.42093599467263E-06 3.51676115917243E-06"
        rpy="0 0 0" />
      <mass
        value="2.87882308178147" />
      <inertia
        ixx="0.0580038949349999"
        ixy="-4.4580434355931E-08"
        ixz="1.06805871602393E-07"
        iyy="0.0385930978636477"
        iyz="9.63979391195808E-08"
        izz="0.0385926926227158" />
    </inertial>
    <visual>
      <origin
        xyz="0 0 0"
        rpy="0 0 0" />
      <geometry>
        <mesh
          filename="package://diff_drive/meshes/visual/tyreRight.STL" />
      </geometry>
      <material
        name="">
        <color
          rgba="0.149019607843137 0.149019607843137 0.149019607843137 1" />
      </material>
    </visual>
    <collision>
      <origin
        xyz="0 0 0"
        rpy="0 0 0" />
      <geometry>
        <mesh
          filename="package://diff_drive/meshes/visual/tyreRight.STL" />
      </geometry>
    </collision>
  </link>
  <joint
    name="tyre_right"
    type="fixed">
    <origin
      xyz="0 0 0"
      rpy="0 0 0" />
    <parent
      link="wheelRight" />
    <child
      link="tyreRight" />
    <axis
      xyz="0 0 0" />
  </joint>
  <link
    name="tireLeft">
    <inertial>
      <origin
        xyz="-0.11009 5.3134E-06 -2.3906E-05"
        rpy="0 0 0" />
      <mass
        value="9.5147" />
      <inertia
        ixx="0.00050921"
        ixy="3.0236E-07"
        ixz="-9.5626E-07"
        iyy="0.00072702"
        iyz="-1.5813E-08"
        izz="0.00072706" />
    </inertial>
    <visual>
      <origin
        xyz="0 0 0"
        rpy="0 0 0" />
      <geometry>
        <mesh
          filename="package://diff_drive/meshes/visual/tireLeft.STL" />
      </geometry>
      <material
        name="">
        <color
          rgba="0.95686 0.95686 0.96078 1" />
      </material>
    </visual>
    <collision>
      <origin
        xyz="0 0 0"
        rpy="0 0 0" />
      <geometry>
        <mesh
          filename="package://diff_drive/meshes/visual/tireLeft.STL" />
      </geometry>
    </collision>
  </link>
  <joint
    name="tire_left"
    type="fixed">
    <origin
      xyz="0.539077625848538 -2.14317773349735 -0.201666803080188"
      rpy="1.5707963267949 0 0" />
    <parent
      link="base_link" />
    <child
      link="tireLeft" />
    <axis
      xyz="0 0 0" />
  </joint>
  <link
    name="wheelLeft">
    <inertial>
      <origin
        xyz="-0.0533246151428166 -4.07197867868803E-07 9.90345227602774E-07"
        rpy="0 0 0" />
      <mass
        value="1.4066983296733" />
      <inertia
        ixx="0.00396065813349289"
        ixy="-5.57709556010084E-09"
        ixz="1.51354720128055E-08"
        iyy="0.00408960235535637"
        iyz="1.95976361170493E-07"
        izz="0.00408893082620729" />
    </inertial>
    <visual>
      <origin
        xyz="0 0 0"
        rpy="0 0 0" />
      <geometry>
        <mesh
          filename="package://diff_drive/meshes/visual/wheelLeft.STL" />
      </geometry>
      <material
        name="">
        <color
          rgba="0.792156862745098 0.819607843137255 0.933333333333333 1" />
      </material>
    </visual>
    <collision>
      <origin
        xyz="0 0 0"
        rpy="0 0 0" />
      <geometry>
        <mesh
          filename="package://diff_drive/meshes/visual/wheelLeft.STL" />
      </geometry>
    </collision>
  </link>
  <joint
    name="wheel_left"
    type="continuous">
    <origin
      xyz="0 0 0"
      rpy="0 0 0" />
    <parent
      link="tireLeft" />
    <child
      link="wheelLeft" />
    <axis
      xyz="-1 0 0" />
    <limit
      effort="1"
      velocity="10" />
  </joint>
  <link
    name="tyreLeft">
    <inertial>
      <origin
        xyz="-0.0680190209861316 -9.36993379330175E-07 3.67542028678614E-06"
        rpy="0 0 0" />
      <mass
        value="2.87882308177231" />
      <inertia
        ixx="0.0580038949352068"
        ixy="2.73071871376998E-08"
        ixz="-1.12470226518638E-07"
        iyy="0.0385930478085845"
        iyz="1.64530994084652E-07"
        izz="0.0385927426781571" />
    </inertial>
    <visual>
      <origin
        xyz="0 0 0"
        rpy="0 0 0" />
      <geometry>
        <mesh
          filename="package://diff_drive/meshes/visual/tyreLeft.STL" />
      </geometry>
      <material
        name="">
        <color
          rgba="0.149019607843137 0.149019607843137 0.149019607843137 1" />
      </material>
    </visual>
    <collision>
      <origin
        xyz="0 0 0"
        rpy="0 0 0" />
      <geometry>
        <mesh
          scale=".0010 .0010 .0010" filename="package://diff_drive/meshes/visual/tyreLeft.STL" />
      </geometry>
    </collision>
  </link>
  <joint
    name="tyre_left"
    type="fixed">
    <origin
      xyz="0 0 0"
      rpy="0 0 0" />
    <parent
      link="wheelLeft" />
    <child
      link="tyreLeft" />
    <axis
      xyz="0 0 0" />
  </joint>




      <!--<xacro:include filename="gazebo.xacro" />-->
      <xacro:include filename="lidar.xacro" />


 </robot>